Workbook

Sheet Portada
B2: CONTROL STORE
B3: Matriz de Requisitos Funcionales
B4: IEEE Std 830-1998 · v3.0
B6: Proyecto: Control Store — Autoservicio Ayuelal
B7: Equipo: Brayan Torres · Nelson Vargas · David Ortegón
B8: Instructor: Albeiro Ramos
B9: Cliente: Humberto Moreno
B10: Programa: Tecnólogo ADSO — SENA, Centro de Servicios Financieros
B11: Versión: v3.0 — 21/06/2026
B13: 30 Requisitos Funcionales principales · 64 sub-requisitos · 5 módulos
B15: Hojas del libro
B16: • Accesos por Rol — los 30 RF y quién accede a cada uno
... B23: EXTEND = flujo condicional / excepción

Sheet Accesos por Rol
A1: CONTROL STORE — Requisitos Funcionales y Accesos por Rol · v3.0
A3: MÓDULO | B3: CÓDIGO | C3: CASO DE USO | D3: ADMIN | E3: VENDEDOR | F3: DOMICILIARIO | G3: CLIENTE | H3: PRIORIDAD | I3: RNF VINCULADOS
A4: USUARIOS | B4: RF01 | C4: Iniciar sesión | D4: ✓ | E4: ✓ | F4: ✓ | G4: — | H4: Alta | I4: RNF01, RNF02, RNF03
A5: USUARIOS | B5: RF02 | C5: Cerrar sesión | D5: ✓ | E5: ✓ | F5: ✓ | G5: — | H5: Alta | I5: RNF02, RNF03
A6: USUARIOS | B6: RF03 | C6: Recuperar contraseña | D6: ✓ | E6: ✓ | F6: ✓ | G6: — | H6: Alta | I6: RNF02, RNF03
A7: USUARIOS | B7: RF04 | C7: Registrar usuario | D7: ✓ | E7: — | F7: — | G7: — | H7: Alta | I7: RNF02, RNF03
A8: USUARIOS | B8: RF05 | C8: Editar usuario | D8: ✓ | E8: — | F8: — | G8: — | H8: Media | I8: RNF03, RNF04
A9: USUARIOS | B9: RF06 | C9: Actualizar estado de usuario | D9: ✓ | E9: — | F9: — | G9: — | H9: Alta | I9: RNF02, RNF04
A10: USUARIOS | B10: RF07 | C10: Cambiar contraseña | D10: ✓ | E10: ✓ | F10: ✓ | G10: — | H10: Media | I10: RNF02, RNF03
A11: INVENTARIO | B11: RF08 | C11: Registrar producto | D11: ✓ | E11: ✓ | F11: — | G11: — | H11: Alta | I11: RNF01, RNF02
A12: INVENTARIO | B12: RF09 | C12: Listar productos | D12: ✓ | E12: ✓ | F12: — | G12: — | H12: Alta | I12: RNF01, RNF05
A13: INVENTARIO | B13: RF10 | C13: Consultar producto | D13: ✓ | E13: ✓ | F13: — | G13: — | H13: Alta | I13: RNF01, RNF05
A14: INVENTARIO | B14: RF11 | C14: Editar producto | D14: ✓ | E14: — | F14: — | G14: — | H14: Media | I14: RNF03, RNF04
... A33: REPORTES | B33: RF30 | C33: Reporte de domicilios | D33: ✓ | E33: — | F33: — | G33: — | H33: Media | I33: RNF01, RNF05
A34: TOTAL (30 RF) | D34: =COUNTIF(D4:D33,"✓") -> 30 | E34: =COUNTIF(E4:E33,"✓") -> 12 | F34: =COUNTIF(F4:F33,"✓") -> 5 | G34: =COUNTIF(G4:G33,"✓") -> 3

Sheet Matriz RF
A1: CONTROL STORE — Matriz de Requisitos Funcionales v3.0 | IEEE Std 830-1998
A2: MÓDULO | B2: CÓDIGO | C2: TIPO | D2: CASO DE USO / SUB-FUNCIÓN | E2: ADMIN | F2: VENDEDOR | G2: DOMICILIARIO | H2: CLIENTE | I2: PRIORIDAD | J2: RNF VINCULADOS
A3: MÓDULO: USUARIOS
A4: USUARIOS | B4: RF01 | C4: Principal | D4: Iniciar sesión | E4: ✓ | F4: ✓ | G4: ✓ | H4: — | I4: Alta | J4: RNF01, RNF02, RNF03
A5: USUARIOS | B5: RF01.1 | C5: INCLUDE | D5: Validar credenciales en BD
A6: USUARIOS | B6: RF01.2 | C6: EXTEND | D6: Error de credenciales incorrectas
A7: USUARIOS | B7: RF01.3 | C7: EXTEND | D7: Bloquear usuario inactivo
A8: USUARIOS | B8: RF02 | C8: Principal | D8: Cerrar sesión | E8: ✓ | F8: ✓ | G8: ✓ | H8: — | I8: Alta | J8: RNF02, RNF03
A9: USUARIOS | B9: RF02.1 | C9: INCLUDE | D9: Validar token de sesión
A10: USUARIOS | B10: RF03 | C10: Principal | D10: Recuperar contraseña | E10: ✓ | F10: ✓ | G10: ✓ | H10: — | I10: Alta | J10: RNF02, RNF03
A11: USUARIOS | B11: RF03.1 | C11: INCLUDE | D11: Enviar email con enlace
A12: USUARIOS | B12: RF03.2 | C12: EXTEND | D12: Error de correo no registrado
A13: USUARIOS | B13: RF04 | C13: Principal | D13: Registrar usuario | E13: ✓ | F13: — | G13: — | H13: — | I13: Alta | J13: RNF02, RNF03
A14: USUARIOS | B14: RF04.1 | C14: INCLUDE | D14: Cifrar contraseña (bcrypt)
A15: USUARIOS | B15: RF04.2 | C15: INCLUDE | D15: Validar correo duplicado
A16: USUARIOS | B16: RF05 | C16: Principal | D16: Editar usuario | E16: ✓ | F16: — | G16: — | H16: — | I16: Media | J16: RNF03, RNF04
A17: USUARIOS | B17: RF05.1 | C17: INCLUDE | D17: Registrar log de auditoría
A18: USUARIOS | B18: RF06 | C18: Principal | D18: Actualizar estado de usuario | E18: ✓ | F18: — | G18: — | H18: — | I18: Alta | J18: RNF02, RNF04
A19: USUARIOS | B19: RF06.2 | C19: EXTEND | D19: Bloquear acceso al desactivar
A20: USUARIOS | B20: RF07 | C20: Principal | D20: Cambiar contraseña | E20: ✓ | F20: ✓ | G20: ✓ | H20: — | I20: Media | J20: RNF02, RNF03
A21: USUARIOS | B21: RF07.1 | C21: INCLUDE | D21: Validar contraseña actual
A22: USUARIOS | B22: RF07.2 | C22: INCLUDE | D22: Cifrar nueva contraseña (bcrypt)
A23: MÓDULO: INVENTARIO
A24: INVENTARIO | B24: RF08 | C24: Principal | D24: Registrar producto | E24: ✓ | F24: ✓ | G24: — | H24: — | I24: Alta | J24: RNF01, RNF02
A25: INVENTARIO | B25: RF08.1 | C25: INCLUDE | D25: Validar código de barras
A26: INVENTARIO | B26: RF08.2 | C26: INCLUDE | D26: Guardar en base de datos
A27: INVENTARIO | B27: RF08.3 | C27: EXTEND | D27: Error de código duplicado
A28: INVENTARIO | B28: RF09 | C28: Principal | D28: Listar productos | E28: ✓ | F28: ✓ | G28: — | H28: — | I28: Alta | J28: RNF01, RNF05
A29: INVENTARIO | B29: RF09.1 | C29: INCLUDE | D29: Consultar BD de inventario
A30: INVENTARIO | B30: RF10 | C30: Principal | D30: Consultar producto | E30: ✓ | F30: ✓ | G30: — | H30: — | I30: Alta | J30: RNF01, RNF05
A31: INVENTARIO | B31: RF10.1 | C31: INCLUDE | D31: Consultar BD de inventario
A32: INVENTARIO | B32: RF10.2 | C32: INCLUDE | D32: Mostrar historial de movimientos
A33: INVENTARIO | B33: RF11 | C33: Principal | D33: Editar producto | E33: ✓ | F33: — | G33: — | H33: — | I33: Media | J33: RNF03, RNF04
A34: INVENTARIO | B34: RF11.1 | C34: INCLUDE | D34: Guardar cambios en BD
A35: INVENTARIO | B35: RF11.2 | C35: INCLUDE | D35: Registrar log de auditoría
A36: INVENTARIO | B36: RF11.3 | C36: EXTEND | D36: Alerta de stock
A37: INVENTARIO | B37: RF12 | C37: Principal | D37: Eliminar producto | E37: ✓ | F37: — | G37: — | H37: — | I37: Baja | J37: RNF03, RNF04
A38: INVENTARIO | B38: RF12.1 | C38: INCLUDE | D38: Confirmar eliminación
A39: INVENTARIO | B39: RF12.2 | C39: INCLUDE | D39: Registrar log de auditoría
A40: INVENTARIO | B40: RF13 | C40: Principal | D40: Alerta de vencimiento y stock mínimo | E40: ✓ | F40: — | G40: — | H40: — | I40: Alta | J40: RNF01, RNF05
...

Sheet Resumen por Módulo
A1: Resumen de Requisitos Funcionales por Módulo · Control Store v3.0
A3: MÓDULO | B3: RF PRINC. | C3: INCLUDE | D3: EXTEND | E3: ADMIN | F3: VENDEDOR | G3: DOMIC. | H3: CLIENTE | I3: ALTA | J3: MEDIA | K3: BAJA
A4: USUARIOS | B4: =COUNTIFS('Matriz RF'!$A$3:$A$101,"USUARIOS",'Matriz RF'!$C$3:$C$101,"Principal") -> 7 | C4: =COUNTIFS('Matriz RF'!$A$3:$A$101,"USUARIOS",'Matriz RF'!$C$3:$C$101,"INCLUDE") -> 8 | D4: =COUNTIFS('Matriz RF'!$A$3:$A$101,"USUARIOS",'Matriz RF'!$C$3:$C$101,"EXTEND") -> 4 | E4: =COUNTIFS('Matriz RF'!$A$3:$A$101,"USUARIOS",'Matriz RF'!$C$3:$C$101,"Principal",'Matriz RF'!$E$3:$E$101,"✓") -> 7 | F4: =COUNTIFS('Matriz RF'!$A$3:$A$101,"USUARIOS",'Matriz RF'!$C$3:$C$101,"Principal",'Matriz RF'!$F$3:$F$101,"✓") -> 4 | G4: =COUNTIFS('Matriz RF'!$A$3:$A$101,"USUARIOS",'Matriz RF'!$C$3:$C$101,"Principal",'Matriz RF'!$G$3:$G$101,"✓") -> 4 | H4: =COUNTIFS('Matriz RF'!$A$3:$A$101,"USUARIOS",'Matriz RF'!$C$3:$C$101,"Principal",'Matriz RF'!$H$3:$H$101,"✓") -> 0 | I4: =COUNTIFS('Matriz RF'!$A$3:$A$101,"USUARIOS",'Matriz RF'!$C$3:$C$101,"Principal",'Matriz RF'!$I$3:$I$101,"Alta") -> 5 | J4: =COUNTIFS('Matriz RF'!$A$3:$A$101,"USUARIOS",'Matriz RF'!$C$3:$C$101,"Principal",'Matriz RF'!$I$3:$I$101,"Media") -> 2 | K4: =COUNTIFS('Matriz RF'!$A$3:$A$101,"USUARIOS",'Matriz RF'!$C$3:$C$101,"Principal",'Matriz RF'!$I$3:$I$101,"Baja") -> 0
A5: INVENTARIO | B5: =COUNTIFS('Matriz RF'!$A$3:$A$101,"INVENTARIO",'Matriz RF'!$C$3:$C$101,"Principal") -> 6 | C5: =COUNTIFS('Matriz RF'!$A$3:$A$101,"INVENTARIO",'Matriz RF'!$C$3:$C$101,"INCLUDE") -> 12 | D5: =COUNTIFS('Matriz RF'!$A$3:$A$101,"INVENTARIO",'Matriz RF'!$C$3:$C$101,"EXTEND") -> 2 | E5: =COUNTIFS('Matriz RF'!$A$3:$A$101,"INVENTARIO",'Matriz RF'!$C$3:$C$101,"Principal",'Matriz RF'!$E$3:$E$101,"✓") -> 6 | F5: =COUNTIFS('Matriz RF'!$A$3:$A$101,"INVENTARIO",'Matriz RF'!$C$3:$C$101,"Principal",'Matriz RF'!$F$3:$F$101,"✓") -> 3 | G5: =COUNTIFS('Matriz RF'!$A$3:$A$101,"INVENTARIO",'Matriz RF'!$C$3:$C$101,"Principal",'Matriz RF'!$G$3:$G$101,"✓") -> 0 | H5: =COUNTIFS('Matriz RF'!$A$3:$A$101,"INVENTARIO",'Matriz RF'!$C$3:$C$101,"Principal",'Matriz RF'!$H$3:$H$101,"✓") -> 0 | I5: =COUNTIFS('Matriz RF'!$A$3:$A$101,"INVENTARIO",'Matriz RF'!$C$3:$C$101,"Principal",'Matriz RF'!$I$3:$I$101,"Alta") -> 4 | J5: =COUNTIFS('Matriz RF'!$A$3:$A$101,"INVENTARIO",'Matriz RF'!$C$3:$C$101,"Principal",'Matriz RF'!$I$3:$I$101,"Media") -> 1 | K5: =COUNTIFS('Matriz RF'!$A$3:$A$101,"INVENTARIO",'Matriz RF'!$C$3:$C$101,"Principal",'Matriz RF'!$I$3:$I$101,"Baja") -> 1
A6: VENTAS | B6: =COUNTIFS('Matriz RF'!$A$3:$A$101,"VENTAS",'Matriz RF'!$C$3:$C$101,"Principal") -> 5 | C6: =COUNTIFS('Matriz RF'!$A$3:$A$101,"VENTAS",'Matriz RF'!$C$3:$C$101,"INCLUDE") -> 10 | D6: =COUNTIFS('Matriz RF'!$A$3:$A$101,"VENTAS",'Matriz RF'!$C$3:$C$101,"EXTEND") -> 3 | E6: =COUNTIFS('Matriz RF'!$A$3:$A$101,"VENTAS",'Matriz RF'!$C$3:$C$101,"Principal",'Matriz RF'!$E$3:$E$101,"✓") -> 5 | F6: =COUNTIFS('Matriz RF'!$A$3:$A$101,"VENTAS",'Matriz RF'!$C$3:$C$101,"Principal",'Matriz RF'!$F$3:$F$101,"✓") -> 3 | G6: =COUNTIFS('Matriz RF'!$A$3:$A$101,"VENTAS",'Matriz RF'!$C$3:$C$101,"Principal",'Matriz RF'!$G$3:$G$101,"✓") -> 0 | H6: =COUNTIFS('Matriz RF'!$A$3:$A$101,"VENTAS",'Matriz RF'!$C$3:$C$101,"Principal",'Matriz RF'!$H$3:$H$101,"✓") -> 0 | I6: =COUNTIFS('Matriz RF'!$A$3:$A$101,"VENTAS",'Matriz RF'!$C$3:$C$101,"Principal",'Matriz RF'!$I$3:$I$101,"Alta") -> 3 | J6: =COUNTIFS('Matriz RF'!$A$3:$A$101,"VENTAS",'Matriz RF'!$C$3:$C$101,"Principal",'Matriz RF'!$I$3:$I$101,"Media") -> 2 | K6: =COUNTIFS('Matriz RF'!$A$3:$A$101,"VENTAS",'Matriz RF'!$C$3:$C$101,"Principal",'Matriz RF'!$I$3:$I$101,"Baja") -> 0
A7: DOMICILIOS | B7: =COUNTIFS('Matriz RF'!$A$3:$A$101,"DOMICILIOS",'Matriz RF'!$C$3:$C$101,"Principal") -> 7 | C7: =COUNTIFS('Matriz RF'!$A$3:$A$101,"DOMICILIOS",'Matriz RF'!$C$3:$C$101,"INCLUDE") -> 9 | D7: =COUNTIFS('Matriz RF'!$A$3:$A$101,"DOMICILIOS",'Matriz RF'!$C$3:$C$101,"EXTEND") -> 8 | E7: =COUNTIFS('Matriz RF'!$A$3:$A$101,"DOMICILIOS",'Matriz RF'!$C$3:$C$101,"Principal",'Matriz RF'!$E$3:$E$101,"✓") -> 7 | F7: =COUNTIFS('Matriz RF'!$A$3:$A$101,"DOMICILIOS",'Matriz RF'!$C$3:$C$101,"Principal",'Matriz RF'!$F$3:$F$101,"✓") -> 0 | G7: =COUNTIFS('Matriz RF'!$A$3:$A$101,"DOMICILIOS",'Matriz RF'!$C$3:$C$101,"Principal",'Matriz RF'!$G$3:$G$101,"✓") -> 1 | H7: =COUNTIFS('Matriz RF'!$A$3:$A$101,"DOMICILIOS",'Matriz RF'!$C$3:$C$101,"Principal",'Matriz RF'!$H$3:$H$101,"✓") -> 3 | I7: =COUNTIFS('Matriz RF'!$A$3:$A$101,"DOMICILIOS",'Matriz RF'!$C$3:$C$101,"Principal",'Matriz RF'!$I$3:$I$101,"Alta") -> 6 | J7: =COUNTIFS('Matriz RF'!$A$3:$A$101,"DOMICILIOS",'Matriz RF'!$C$3:$C$101,"Principal",'Matriz RF'!$I$3:$I$101,"Media") -> 1 | K7: =COUNTIFS('Matriz RF'!$A$3:$A$101,"DOMICILIOS",'Matriz RF'!$C$3:$C$101,"Principal",'Matriz RF'!$I$3:$I$101,"Baja") -> 0
A8: REPORTES | B8: =COUNTIFS('Matriz RF'!$A$3:$A$101,"REPORTES",'Matriz RF'!$C$3:$C$101,"Principal") -> 5 | C8: =COUNTIFS('Matriz RF'!$A$3:$A$101,"REPORTES",'Matriz RF'!$C$3:$C$101,"INCLUDE") -> 5 | D8: =COUNTIFS('Matriz RF'!$A$3:$A$101,"REPORTES",'Matriz RF'!$C$3:$C$101,"EXTEND") -> 3 | E8: =COUNTIFS('Matriz RF'!$A$3:$A$101,"REPORTES",'Matriz RF'!$C$3:$C$101,"Principal",'Matriz RF'!$E$3:$E$101,"✓") -> 5 | F8: =COUNTIFS('Matriz RF'!$A$3:$A$101,"REPORTES",'Matriz RF'!$C$3:$C$101,"Principal",'Matriz RF'!$F$3:$F$101,"✓") -> 2 | G8: =COUNTIFS('Matriz RF'!$A$3:$A$101,"REPORTES",'Matriz RF'!$C$3:$C$101,"Principal",'Matriz RF'!$G$3:$G$101,"✓") -> 0 | H8: =COUNTIFS('Matriz RF'!$A$3:$A$101,"REPORTES",'Matriz RF'!$C$3:$C$101,"Principal",'Matriz RF'!$H$3:$H$101,"✓") -> 0 | I8: =COUNTIFS('Matriz RF'!$A$3:$A$101,"REPORTES",'Matriz RF'!$C$3:$C$101,"Principal",'Matriz RF'!$I$3:$I$101,"Alta") -> 0 | J8: =COUNTIFS('Matriz RF'!$A$3:$A$101,"REPORTES",'Matriz RF'!$C$3:$C$101,"Principal",'Matriz RF'!$I$3:$I$101,"Media") -> 3 | K8: =COUNTIFS('Matriz RF'!$A$3:$A$101,"REPORTES",'Matriz RF'!$C$3:$C$101,"Principal",'Matriz RF'!$I$3:$I$101,"Baja") -> 2
A9: TOTAL | B9: =SUM(B4:B8) -> 30 | C9: =SUM(C4:C8) -> 44 | D9: =SUM(D4:D8) -> 20 | E9: =SUM(E4:E8) -> 30 | F9: =SUM(F4:F8) -> 12 | G9: =SUM(G4:G8) -> 5 | H9: =SUM(H4:H8) -> 3 | I9: =SUM(I4:I8) -> 18 | ... K9: =SUM(K4:K8) -> 3
A11: Leyenda de prioridades
A12: Alta | B12: Funcionalidad crítica para el negocio
A13: Media | B13: Importante pero no bloqueante
A14: Baja | B14: Deseable a futuro

Sheet RNF
A1: Requisitos No Funcionales — Control Store v3.0
A2: CÓDIGO | B2: NOMBRE | C2: DESCRIPCIÓN RESUMIDA | D2: PRIORIDAD
A3: RNF01 | B3: Rendimiento | C3: El sistema debe responder en menos de 2 segundos para el 95% de las transacciones de venta y consultas de inventario. El tiempo de carga de páginas no deberá superar los 3 segundos en conexiones de banda ancha estándar. | D3: Alta
A4: RNF02 | B4: Seguridad de acceso | C4: El sistema debe garantizar que cada usuario acceda únicamente a las funciones correspondientes a su rol (ADMIN, VENDEDOR, DOMICILIARIO). Las contraseñas deben almacenarse cifradas con algoritmo bcrypt. Solo el ADMIN podrá anular ventas, modificar precios y consultar reportes financieros. | D4: Alta
A5: RNF03 | B5: Seguridad de datos | C5: El sistema debe cifrar la comunicación entre cliente y servidor mediante HTTPS con certificado SSL en producción. Los datos personales de clientes y empleados deberán manejarse conforme a la Ley 1581 de 2012 de protección de datos personales (Colombia). | D5: Alta
A6: RNF04 | B6: Auditoría | C6: El sistema debe registrar en un log de auditoría todas las acciones críticas: inicios de sesión, anulaciones de ventas, cambios de precio, creación y eliminación de usuarios. Cada registro deberá incluir fecha, hora, usuario y descripción de la acción. | D6: Alta
A7: RNF05 | B7: Disponibilidad | C7: El sistema debe estar disponible el 99% del tiempo en horario comercial (7:00 AM – 10:00 PM). En caso de fallo, el tiempo de recuperación no deberá superar los 30 minutos. | D7: Alta
A8: RNF06 | B8: Concurrencia | C8: El sistema debe soportar al menos 5 usuarios simultáneos (Administrador, 2 Vendedores, Domiciliario, Chatbot) sin degradación del rendimiento. El módulo de chatbot de WhatsApp deberá procesar al menos 10 conversaciones simultáneas sin pérdida de datos. | D8: Media
A9: RNF07 | B9: Usabilidad | C9: El sistema debe tener una interfaz web responsiva (Bootstrap 5) que funcione correctamente en celulares, tablets y computadores. La navegación deberá ser intuitiva para usuarios con conocimientos básicos de informática. El chatbot de WhatsApp deberá usar lenguaje claro y opciones numeradas fáciles de entender. | D9: Alta
A10: RNF08 | B10: Portabilidad | C10: El sistema debe poder ejecutarse sobre MySQL 8 tanto en ambiente de pruebas como en producción, sin requerir cambios en el código fuente. El sistema deberá poder desplegarse en servidores Linux (Ubuntu 22.04) o Windows Server. | D10: Media
A11: RNF09 | B11: Mantenibilidad | C11: El código fuente del sistema debe estar organizado siguiendo el patrón MVC de Laravel (Model – View – Controller), con comentarios en funciones clave y nombres de variables descriptivos en español. Cada módulo debe estar separado con sus propios controladores y modelos independientes. | D11: Media
A12: RNF10 | B12: Idioma y localización | C12: El sistema debe estar completamente en español colombiano. Los formatos de fecha deben ser DD/MM/AAAA, la moneda en pesos colombianos (COP $) y las horas en formato 12h AM/PM. El chatbot de WhatsApp deberá responder en español con vocabulario cotidiano y amigable. | D12: Media
