Workbook

Sheet ESTIMADO TOTAL PROYECTO
A1: Aleyual — Control Store | ESTIMADO TOTAL DEL PROYECTO
A2: Feb 2026 → Sep 2027 · 20 meses · Prestación de Servicios · 7 fases · 30 entregables
A4: # | B4: CATEGORÍA DE COSTO | C4: % del Proyecto | D4: Hoja fuente | E4: VALOR
A5: I | B5: RECURSOS PROFESIONALES | C5: =IFERROR(E5/E14,0) -> 0.6189786 | D5: Ver hoja | E5: ='RECURSOS HUM'!J10 -> 161733333
A6: II | B6: RECURSOS TECNOLÓGICOS | C6: =IFERROR(E6/E14,0) -> 0.0026014438 | D6: Ver hoja | E6: =ROUND('RECURSOS TECNOLÓGICOS'!E40,0) -> 679733
A7: III | B7: GASTOS ADMINISTRATIVOS | C7: =IFERROR(E7/E14,0) -> 0.10305764 | D7: Ver hoja | E7: =ROUND(GASTOS!E24,0) -> 26928000
B8: SUBTOTAL BASE | E8: =SUM(E5:E7) -> 189341066
A10: IV | B10: IMPREVISTOS (riesgos y contingencias) | C10: 0.2 | E10: =ROUND(E8*0.2,0) -> 37868213
A11: V | B11: GANANCIA / UTILIDAD DEL PROYECTO | C11: 0.15 | E11: =ROUND((E8+E10)*0.15,0) -> 34081392
A14: COSTO TOTAL DEL PROYECTO — ¿Cuánto cuesta el Proyecto? | E14: =E8+E10+E11 -> 261290671
A16: • Imprevistos 20%: cubre riesgos técnicos, retrasos, cambios de requerimientos. Estándar en proyectos de software colombianos.
A17: • Ganancia 15%: margen de utilidad sobre el costo total (base + imprevistos). Ref: PMI / PMBOK Colombia.
A18: • Fuentes salariales: Glassdoor Colombia 2025-2026 · Indeed.com.co · tusalario.org/colombia
A19: • Fuentes cloud: aws.amazon.com/es/pricing · calculator.aws · Tasa USD/COP: $4.200 (BanRep jun 2026)

Sheet PLANEACIÓN
A1: Aleyual — Control Store | Planeación de Actividades | Feb 2026 → Sep 2027
A2: ITEM | B2: # | C2: ACTIVIDAD / ENTREGABLE | D2: EVIDENCIA | E2: RESPONSABLE | F2: INICIO | G2: FIN | H2: ✓ Hecho | I2: % AVANCE
A3: 1 | B3: 1 | C3: ESPECIFICACIÓN DE REQUISITOS
B4: 1.1 | C4: Analizar datos y determinar necesidades del cliente | D4: Documento de Análisis | E4: Analista | F4: 46055 | G4: 46081 | H4: ☑ | I4: 100
B5: 1.2 | C5: Elaborar el Diagrama de Procesos | D5: Diagrama de Procesos | E5: Analista | F5: 46082 | G5: 46091 | H5: ☑ | I5: 100
B6: 1.3 | C6: Elaborar Informe de Requisitos (IEEE-830) | D6: Documento IEEE-830 | E6: Analista | F6: 46092 | G6: 46108 | H6: ☑ | I6: 100
A7: 2 | B7: 2 | C7: ANÁLISIS Y DISEÑO
B8: 2.1 | C8: Diagramar los Casos de Uso | D8: Diagrama Casos de Uso | E8: Arquitecto | F8: 46125 | G8: 46145 | H8: ☑ | I8: 100
B9: 2.2 | C9: Plantillas de Casos de Uso Extendido | D9: Casos de Uso Extendido | E9: Arquitecto | F9: 46146 | G9: 46169 | H9: ☐ | I9: 90
B10: 2.3 | C10: Estimación de costos — Diagrama de Gantt | D10: Cronograma / Gantt | E10: Adm. Proyecto | F10: 46170 | G10: 46190 | H10: ☐ | I10: 50
B11: 2.4 | C11: Control de versiones SCV | D11: Repositorio Git | E11: Dev Full-Stack | F11: 46191 | G11: 46206 | H11: ☐ | I11: 0
A12: 3 | B12: 3 | C12: DISEÑO TÉCNICO DE DATOS Y ARQUITECTURA
B13: 3.1 | C13: Modelo Entidad-Relación / Crows Foot | D13: MER / Diagrama BD | E13: Gestor BD | F13: 46223 | G13: 46237 | H13: ☐ | I13: 0
B14: 3.2 | C14: Normalización 3FN | D14: Modelo Normalizado | E14: Gestor BD | F14: 46235 | G14: 46249 | H14: ☐ | I14: 0
B15: 3.3 | C15: Diccionario de Datos | D15: Diccionario | E15: Gestor BD | F15: 46250 | G15: 46265 | H15: ☐ | I15: 0
B16: 3.4 | C16: Diagrama de Clases UML | D16: UML Clases | E16: Arquitecto | F16: 46266 | G16: 46282 | H16: ☐ | I16: 0
B17: 3.5 | C17: Diagrama de Distribución UML | D17: UML Despliegue | E17: Arquitecto | F17: 46280 | G17: 46294 | H17: ☐ | I17: 0
B18: 3.6 | C18: Prototipo navegable HTML/CSS/JS | D18: Prototipo Web | E18: Dev Full-Stack | F18: 46289 | G18: 46305 | H18: ☐ | I18: 0
B19: 3.7 | C19: SCV — commits y ramas | D19: Repositorio Git | E19: Dev Full-Stack | F19: 46300 | G19: 46306 | H19: ☐ | I19: 0
A20: 4 | B20: 4 | C20: DESARROLLO BASE DE DATOS Y FRONTEND
B21: 4.1 | C21: Base de Datos DDL (SQL) | D21: Script DDL | E21: Gestor BD | F21: 46314 | G21: 46329 | H21: ☐ | I21: 0
B22: 4.2 | C22: Script DML — Joins/subconsultas | D22: Script DML | E22: Gestor BD | F22: 46326 | G22: 46343 | H22: ☐ | I22: 0
B23: 4.3 | C23: Seguridad BD — bcrypt/sha256 | D23: Encriptación | E23: Gestor BD | F23: 46340 | G23: 46357 | H23: ☐ | I23: 0
B24: 4.4 | C24: Frontend Blade + Sanctum Auth | D24: Aplicación Web | E24: Dev Full-Stack | F24: 46354 | G24: 46375 | H24: ☐ | I24: 0
B25: 4.5 | C25: SCV — historial de versiones | D25: Repositorio Git | E25: Dev Full-Stack | F25: 46396 | G25: 46409 | H25: ☐ | I25: 0
A26: 5 | B26: 5 | C26: INTEGRACIÓN API REST
B27: 5.1 | C27: API REST + Sanctum + CORS + Postman | D27: Documentación API | E27: Dev Backend | F27: 46414 | G27: 46437 | H27: ☐ | I27: 0
B28: 5.2 | C28: Frontend consume API REST (80% avance) | D28: App Integrada | E28: Dev Full-Stack | F28: 46432 | G28: 46473 | H28: ☐ | I28: 0
B29: 5.3 | C29: SCV — commits y ramas | D29: Repositorio Git | E29: Dev Full-Stack | F29: 46468 | G29: 46479 | H29: ☐ | I29: 0
A30: 6 | B30: 6 | C30: APP MÓVIL Y CIERRE DE FRONTEND
B31: 6.1 | C31: Solución web 100% completa | D31: Aplicación Completa | E31: Dev Full-Stack | F31: 46498 | G31: 46518 | H31: ☐ | I31: 0
B32: 6.2 | C32: API REST documentada en Swagger | D32: Swagger Docs | E32: Dev Backend | F32: 46514 | G32: 46533 | H32: ☐ | I32: 0
B33: 6.3 | C33: App móvil — metodología ágil | D33: Sprint Backlog | E33: Dev Full-Stack | F33: 46527 | G33: 46554 | H33: ☐ | I33: 0
B34: 6.4 | C34: App móvil consume API REST | D34: App Móvil | E34: Dev Full-Stack | F34: 46550 | G34: 46571 | H34: ☐ | I34: 0
B35: 6.5 | C35: SCV — entrega trimestral | D35: Repositorio Git | E35: Dev Full-Stack | F35: 46568 | G35: 46575 | H35: ☐ | I35: 0
A36: 7 | B36: 7 | C36: PRUEBAS, CALIDAD Y DESPLIEGUE
B37: 7.1 | C37: Pruebas de software | D37: Casos de Prueba | E37: Tester | F37: 46596 | G37: 46610 | H37: ☐ | I37: 0
B38: 7.2 | C38: Planes de instalación y respaldo | D38: Plan de Despliegue | E38: Adm. Proyecto | F38: 46608 | G38: 46620 | H38: ☐ | I38: 0
B39: 7.3 | C39: Modelo de calidad ISO/IEC 25010 | D39: Informe de Calidad | E39: Tester | F39: 46618 | G39: 46628 | H39: ☐ | I39: 0
B40: 7.4 | C40: Manuales técnico y de usuario | D40: Manuales | E40: Tester | F40: 46626 | G40: 46636 | H40: ☐ | I40: 0
...

Sheet SCRUM — ÁGIL
A1: Aleyual — Control Store | SCRUM — Metodología Ágil | Feb 2026 → Sep 2027
A2: Sistema de Autoservicio: Módulos Inventario · Ventas · Caja · Domicilios | 15 Sprints | 175 Story Points totales
A4: ROL | C4: RESPONSABLE | F4: RESPONSABILIDAD EN CONTROL STORE
A5: Product Owner | C5: Administrador Proyecto | F5: Define y prioriza el Product Backlog. Representa al cliente (Autoservicio Aleyual). Acepta o rechaza entregables de cada Sprint.
A6: Scrum Master | C6: Arquitecto de Software | F6: Facilita las ceremonias Scrum. Elimina impedimentos técnicos. Asegura que el equipo siga el proceso ágil y la arquitectura definida.
A7: Dev Team | C7: Dev Full-Stack (×2), Gestor BD, Dev Backend, Tester | F7: Equipo autoorganizado. Transforma el Sprint Backlog en incrementos funcionales. Estima las historias de usuario y cumple los compromisos del Sprint.
A9: CEREMONIAS SCRUM — Control Store
A10: # | B10: Ceremonia | C10: Frecuencia | D10: Duración | E10: Participantes | F10: Entregable
A11: 1 | B11: Sprint Planning | C11: Inicio de cada Sprint · ≤ 2 horas | E11: Todo el equipo Scrum | G11: Sprint Backlog priorizado + compromiso del Sprint
A12: 2 | B12: Daily Scrum | C12: Cada día hábil del Sprint · 15 minutos | E12: Dev Team + Scrum Master | G12: Plan del día: ¿Qué hice? ¿Qué haré? ¿Impedimentos?
A13: 3 | B13: Sprint Review | C13: Final de cada Sprint · ≤ 1 hora | E13: Equipo + Product Owner | G13: Demo del Incremento funcional. PO acepta o rechaza US.
A14: 4 | B14: Sprint Retrospectiva | C14: Final de cada Sprint · ≤ 45 minutos | E14: Todo el equipo Scrum | G14: Plan de mejora del proceso para el siguiente Sprint
A15: 5 | B15: Backlog Refinement | C15: 1 vez por semana (mitad del Sprint) · ≤ 1 hora | E15: PO + Dev Team | G15: US estimadas, descompuestas y listas para el próximo Sprint
A17: PRODUCT BACKLOG — Historias de Usuario (30 US · 175 Story Points)
A18: ID | B18: ÉPICA | C18: ROL | D18: HISTORIA DE USUARIO | E18: CRITERIOS DE ACEPTACIÓN | F18: SP | G18: PRIORIDAD | H18: SPRINT | I18: INICIO | J18: FIN | K18: ESTADO
A19: US-01 | B19: Autenticación | C19: Como Administrador | D19: quiero Iniciar sesión con usuario y contraseña segura | E19: Login con credenciales / Token Sanctum / Redirección por rol | F19: 5 | G19: Alta | H19: Sprint 7 | I19: 19 Oct 2026 | J19: 30 Oct 2026 | K19: Pendiente
A20: US-02 | B20: Autenticación | C20: Como Sistema | D20: quiero Gestionar roles Admin, Vendedor y Domiciliario | E20: Roles en BD / Permisos por módulo / Middleware Sanctum | F20: 8 | G20: Alta | H20: Sprint 7 | I20: 19 Oct 2026 | J20: 06 Nov 2026 | K20: Pendiente
A21: US-03 | B21: Autenticación | C21: Como Administrador | D21: quiero Crear y gestionar usuarios del sistema | E21: CRUD usuarios / Asignar rol / Cambio de contraseña | F21: 5 | G21: Alta | H21: Sprint 8 | I21: 09 Nov 2026 | J21: 20 Nov 2026 | K21: Pendiente
A22: US-04 | B22: Inventario | C22: Como Administrador | D22: quiero Registrar productos con nombre, precio, stock y categoría | E22: Formulario producto / Validaciones / Guardar en BD | F22: 5 | G22: Alta | H22: Sprint 8 | I22: 09 Nov 2026 | J22: 20 Nov 2026 | K22: Pendiente
A23: US-05 | B23: Inventario | C23: Como Vendedor | D23: quiero Buscar productos por nombre o código de barras | E23: Búsqueda en tiempo real / Filtros por categoría | F23: 3 | G23: Alta | H23: Sprint 9 | I23: 23 Nov 2026 | J23: 04 Dic 2026 | K23: Pendiente
A24: US-06 | B24: Inventario | C24: Como Administrador | D24: quiero Actualizar el stock de productos manualmente | E24: Registro de ajuste / Motivo obligatorio / Historial | F24: 3 | G24: Media | H24: Sprint 9 | I24: 23 Nov 2026 | J24: 04 Dic 2026 | K24: Pendiente
A25: US-07 | B25: Inventario | C25: Como Sistema | D25: quiero Alertar cuando el stock esté por debajo del umbral | E25: Umbral configurable / Alerta visual en dashboard | F25: 2 | G25: Media | H25: Sprint 9 | I25: 07 Dic 2026 | J25: 11 Dic 2026 | K25: Pendiente
A26: US-08 | B26: Inventario | C26: Como Administrador | D26: quiero Gestionar categorías y subcategorías de productos | E26: CRUD categorías / Jerarquía padre-hijo | F26: 3 | G26: Media | H26: Sprint 8 | I26: 23 Nov 2026 | J26: 04 Dic 2026 | K26: Pendiente
A27: US-09 | B27: Inventario | C27: Como Administrador | D27: quiero Ver historial de movimientos de inventario | E27: Lista de movimientos / Filtro fecha-producto / Exportar | F27: 5 | G27: Baja | H27: Sprint 10 | I27: 11 Ene 2027 | J27: 22 Ene 2027 | K27: Pendiente
A28: US-10 | B28: Ventas | C28: Como Vendedor | D28: quiero Agregar productos al carrito de compra | E28: Búsqueda rápida / Cantidad ajustable / Total automático | F28: 5 | G28: Alta | H28: Sprint 9 | I28: 07 Dic 2026 | J28: 18 Dic 2026 | K28: Pendiente
A29: US-11 | B29: Ventas | C29: Como Vendedor | D29: quiero Procesar una venta y generar recibo imprimible | E29: Registro venta / IVA automático / Recibo PDF | F29: 8 | G29: Alta | H29: Sprint 10 | I29: 11 Ene 2027 | J29: 29 Ene 2027 | K29: Pendiente
A30: US-12 | B30: Ventas | C30: Como Vendedor | D30: quiero Aplicar descuentos a productos o al total de la venta | E30: Descuento % o valor / Registro en venta / Autorización | F30: 3 | G30: Media | H30: Sprint 10 | I30: 25 Ene 2027 | J30: 05 Feb 2027 | K30: Pendiente
... A48: US-30 | B48: App Móvil | C48: Como Cliente | D48: quiero Hacer pedidos de domicilio desde la app móvil | E48: Catálogo / Carrito / Dirección / Pago contra entrega | F48: 13 | G48: Baja | H48: Sprint 14 | I48: 07 Jul 2027 | J48: 18 Jul 2027 | K48: Pendiente
A49: TOTAL STORY POINTS DEL PRODUCT BACKLOG | F49: =SUM(F19:F48) -> 175 | G49: Alta: =COUNTIF(G19:G48,"Alta") historias | J49: =COUNTIF(G19:G48,"Alta")&" Alta / "&COUNTIF(G19:G48,"Media")&" Media / "&COUNTIF(G19:G48,"Baja")&" Baja" -> 17 Alta / 10 Media / 3 Baja
A51: SPRINT PLANNING — Planificación de los 15 Sprints | Duración: 3–4 semanas por Sprint
A52: # | B52: SPRINT | C52: PERÍODO | D52: OBJETIVO / ENTREGABLE | E52: HISTORIAS INCLUIDAS | F52: SP | G52: ACUM. | H52: TRIMESTRE | I52: FASE | J52: ESTADO | K52: VELOC.
A53: 0 | B53: Sprint 0 | C53: 02 Feb – 06 Mar 2026 | D53: Kickoff: Análisis de requisitos, IEEE-830, configuración del proyecto | E53: — | F53: — | G53: — | H53: T1 | I53: Especificación | J53: Completado | K53: —
A54: 1 | B54: Sprint 1 | C54: 09 Mar – 01 Abr 2026 | D54: Diagramas de Casos de Uso y plantillas extendidas | E54: US planning | F54: — | G54: — | H54: T2 | I54: Análisis | J54: Completado | K54: —
A55: 2 | B55: Sprint 2 | C55: 13 Abr – 08 May 2026 | D55: Wireframes y prototipos Figma. Setup repositorio Git/SCV | E55: US planning | F55: — | G55: — | H55: T2 | I55: Diseño | J55: Completado | K55: —
A56: 3 | B56: Sprint 3 | C56: 11 May – 05 Jun 2026 | D56: Modelo relacional Crows Foot, diccionario de datos, normalización 3FN | E56: US planning | F56: — | G56: — | H56: T3 | I56: Diseño BD | J56: Completado | K56: —
A57: 4 | B57: Sprint 4 | C57: 08 Jun – 03 Jul 2026 | D57: Diagramas UML (Clases + Distribución). Prototipo navegable HTML/CSS/JS | E57: US planning | F57: — | G57: — | H57: T3 | I57: Arquitectura | J57: Completado | K57: —
A58: 5 | B58: Sprint 5 | C58: 20 Jul – 14 Ago 2026 | D58: DDL/DML SQL. Seguridad BD: bcrypt, sha256, roles | E58: US planning | F58: — | G58: — | H58: T3 | I58: Base de Datos | J58: Completado | K58: —
A59: 6 | B59: Sprint 6 | C59: 17 Ago – 09 Oct 2026 | D59: Prototipo navegable completo. Frontend base Blade + configuración Sanctum | E59: US planning | F59: — | G59: — | H59: T3-T4 | I59: Prototipo | J59: En Progreso | K59: —
A60: 7 | B60: Sprint 7 | C60: 19 Oct – 06 Nov 2026 | D60: US-01, US-02 — Sistema de autenticación y roles | E60: US-01, US-02 | F60: 13 | G60: 13 | H60: T4 | I60: Desarrollo | J60: Pendiente | K60: 13
A61: 8 | B61: Sprint 8 | C61: 09 Nov – 04 Dic 2026 | D61: US-03, US-04, US-08 — Gestión usuarios, productos y categorías | E61: US-03,04,08 | F61: 13 | G61: 26 | H61: T4 | I61: Desarrollo | J61: Pendiente | K61: 13
...

Sheet RECURSOS HUM
A1: Aleyual — Control Store | Recursos Humanos | Prestación de Servicios (Art. 34 C.S.T.)
A2: ITEM | B2: PROFESIONAL | C2: CANT | D2: SALARIO MENSUAL | E2: MES | F2: V/DIA | G2: HORAS/DIA | H2: V/HORA | I2: DIAS | J2: SALARIO REAL
A3: 1 | B3: Arquitecto de Software | C3: 1 | D3: 5500000 | E3: 30 | F3: =D3/E3 -> 183333.33 | G3: 8 | H3: =F3/G3 -> 22916.667 | I3: 160 | J3: =ROUND(F3*I3*C3,0) -> 29333333
A4: 2 | B4: Administrador Proyecto | C4: 1 | D4: 4800000 | E4: 30 | F4: =D4/E4 -> 160000 | G4: 8 | H4: =F4/G4 -> 20000 | I4: 280 | J4: =ROUND(F4*I4*C4,0) -> 44800000
A5: 3 | B5: Analista | C5: 2 | D5: 3000000 | E5: 30 | F5: =D5/E5 -> 100000 | G5: 6 | H5: =F5/G5 -> 16666.667 | I5: 45 | J5: =ROUND(F5*I5*C5,0) -> 9000000
A6: 4 | B6: Gestor de Bases de Datos | C6: 1 | D6: 4000000 | E6: 30 | F6: =D6/E6 -> 133333.33 | G6: 5 | H6: =F6/G6 -> 26666.667 | I6: 80 | J6: =ROUND(F6*I6*C6,0) -> 10666667
A7: 5 | B7: Desarrollador Web | C7: 1 | D7: 3800000 | E7: 30 | F7: =D7/E7 -> 126666.67 | G7: 8 | H7: =F7/G7 -> 15833.333 | I7: 200 | J7: =ROUND(F7*I7*C7,0) -> 25333333
A8: 6 | B8: Desarrollador Backend | C8: 3 | D8: 4200000 | E8: 30 | F8: =D8/E8 -> 140000 | G8: 8 | H8: =F8/G8 -> 17500 | I8: 90 | J8: =ROUND(F8*I8*C8,0) -> 37800000
A9: 7 | B9: Tester | C9: 1 | D9: 3200000 | E9: 30 | F9: =D9/E9 -> 106666.67 | G9: 8 | H9: =F9/G9 -> 13333.333 | I9: 45 | J9: =ROUND(F9*I9*C9,0) -> 4800000
A10: PARCIAL | J10: =SUM(J3:J9) -> 161733333
A12: NOTA: La contratación de los profesionales se hará por Prestación de Servicios según el tiempo que se requiera en el proyecto (Art. 34 C.S.T.)
A14: Fuentes de honorarios (prestación de servicios, mercado Colombia 2026):
A15: • Glassdoor Colombia: glassdoor.com.mx/Sueldos/colombia-desarrollador → rango $3.0M–$6.8M/mes para Dev Software
A16: • Indeed Colombia: co.indeed.com/career/desarrollador-de-software/salaries → promedio $3.1M/mes (actualizado mayo 2026)
A17: • tusalario.org/colombia → rango $3.2M–$17.4M/mes para Dev Software (2026)
A18: • Coderhouse Colombia: coderhouse.com/us/sueldos → Full Stack Senior desde $9M/mes, Mid-level $5M–$7M/mes
A19: • Glassdoor Bogotá: $3.8M/mes promedio Desarrollador (rango $2.2M–$12.5M/mes)

Sheet SERVIDOR Y EQUIPOS
A1: Aleyual — Control Store | Equipos de Cómputo | 4 PCs trabajadores + 1 Servidor (ya existente)
A2: 4 trabajadores: $3.840.000 c/u (solo depreciación va al presupuesto) | Servidor: YA LO TIENE Aleyual — $0 de compra
A4: RESUMEN — 5 EQUIPOS DEL PROYECTO
A5: # | B5: EQUIPO | C5: ROL EN EL PROYECTO | D5: TIPO | E5: VALOR | F5: ¿SE PRESUPUESTA? | G5: NOTA
A6: 1 | B6: PC 1 — Trabajador A | C6: Estación de desarrollo | D6: Propio del trabajador | E6: 3840000 | F6: Solo depreciación | G6: 18 meses trabajados
A7: 2 | B7: PC 2 — Trabajador B | C7: Estación de desarrollo | D7: Propio del trabajador | E7: 3840000 | F7: Solo depreciación | G7: 18 meses trabajados
A8: 3 | B8: PC 4 — Trabajador C | C8: Estación de desarrollo | D8: Propio del trabajador | E8: 3840000 | F8: Solo depreciación | G8: 18 meses trabajados
A9: 4 | B9: PC 5 — Trabajador D | C9: Estación de desarrollo | D9: Propio del trabajador | E9: 3840000 | F9: Solo depreciación | G9: 18 meses trabajados
A10: 5 | B10: PC 3 — Servidor de la tienda | C10: Corre API+BD+Frontend en Aleyual | D10: YA EXISTE — propiedad de Aleyual | E10: 4580000 | F10: NO — equipo ya propio | G10: Sin compra ni depreciación
A11: VALOR TOTAL 5 EQUIPOS (referencia de mercado) | E11: =SUM(E6:E10) -> 19940000 | F11: Solo se presupuesta: depreciación 4 PCs trabajadores. PC3 = $0 (ya existe)
A13: PC 1 y PC 2 — ESTACIONES DE DESARROLLO (idénticas · depreciación por 18 MESES trabajados)
A14: # | B14: COMPONENTE | C14: MODELO / ESPECIFICACIÓN | D14: FUNCIÓN | E14: PRECIO | F14: JUSTIFICACIÓN | G14: PRIORIDAD
A15: 1 | B15: Procesador (CPU) | C15: AMD Ryzen 5 5600 · 6C/12T · 3.5–4.4 GHz · 35 MB caché AM4 | D15: Procesamiento | E15: 680000 | F15: Compila assets + corre servidor local de desarrollo simultáneamente sin lag | G15: Crítico
A16: 2 | B16: Tarjeta madre | C16: MSI B550-A PRO · AM4 · ATX · 4 slots DDR4 · PCIe 4.0 | D16: Placa base | E16: 480000 | F16: Plataforma AM4 estable. PCIe 4.0 para SSD rápido de desarrollo | G16: Crítico
A17: 3 | B17: Memoria RAM | C17: 16 GB DDR4 3200 MHz · Kingston Fury Beast · 2×8 GB | D17: RAM | E17: 360000 | F17: VS Code + Chrome + Postman + Laravel local corriendo a la vez sin swap | G17: Crítico
A18: 4 | B18: SSD NVMe 1 TB | C18: Kingston NV2 M.2 · Lectura 3.500 MB/s | D18: Almacenamiento | E18: 320000 | F18: OS + proyectos + entornos node_modules + BD local de pruebas | G18: Crítico
A19: 5 | B19: Fuente de poder | C19: Thermaltake Smart 600W · 80+ Bronze · ATX | D19: Alimentación | E19: 240000 | F19: 600W eficiente para Ryzen 5 sin GPU dedicada. Protecciones eléctricas | G19: Crítico
A20: 6 | B20: Gabinete | C20: Thermaltake Versa H17 · Micro-ATX · Panel lateral | D20: Carcasa | E20: 160000 | F20: Compacto para escritorio de trabajo. Buen flujo de aire | G20: Medio
A21: 7 | B21: Monitor 24" FHD | C21: LG 24MK430H · FHD 1080p IPS · 75Hz · HDMI | D21: Display | E21: 660000 | F21: 24" IPS para sesiones largas de programación. Colores precisos para UI/UX | G21: Crítico
A22: 8 | B22: Teclado | C22: Logitech K280e Pro USB · Silencioso · Ergonómico | D22: Periférico | E22: 100000 | F22: Cómodo para largas sesiones de código. Silencioso en trabajo compartido | G22: Alto
A23: 9 | B23: Mouse | C23: Logitech M100 USB · 1000 DPI · Plug & Play | D23: Periférico | E23: 50000 | F23: Confiable y preciso. Sin drivers. Compatible Ubuntu y Windows | G23: Alto
A24: 10 | B24: UPS 750VA | C24: Forza NT-751 · 750VA/375W · 6 tomas · Protección picos | D24: Energía | E24: 380000 | F24: Protege de picos eléctricos frecuentes en Colombia. Esencial para no perder trabajo | G24: Alto
A25: 11 | B25: Audífonos + Mic | C25: HyperX Cloud Stinger · USB · Micrófono integrado | D25: Audio | E25: 230000 | F25: Reuniones Daily Scrum, Sprint Review y comunicación remota con el equipo | G25: Medio
A26: 12 | B26: Webcam HD | C26: Logitech C270 · 720p · USB · Clip monitor | D26: Video | E26: 180000 | F26: Demos Sprint Review, videoconferencias con instructor SENA | G26: Medio
A27: TOTAL PC 1 / PC 2 (cada estación) — valor de referencia, SOLO se presupuesta depreciación | E27: =SUM(E15:E26) -> 3840000
A29: PC 4 y PC 5 — NUEVAS ESTACIONES DE DESARROLLO (idénticas a PC1/PC2 · depreciación por 18 MESES trabajados)
A30: # | B30: COMPONENTE | C30: MODELO / ESPECIFICACIÓN | D30: FUNCIÓN | E30: PRECIO | F30: JUSTIFICACIÓN | G30: PRIORIDAD
A31: 1 | B31: Procesador (CPU) | C31: AMD Ryzen 5 5600 · 6C/12T · 3.5–4.4 GHz · 35 MB caché AM4 | D31: Procesamiento | E31: 680000 | F31: Compila assets + corre servidor local de desarrollo simultáneamente sin lag | G31: Crítico
A32: 2 | B32: Tarjeta madre | C32: MSI B550-A PRO · AM4 · ATX · 4 slots DDR4 · PCIe 4.0 | D32: Placa base | E32: 480000 | F32: Plataforma AM4 estable. PCIe 4.0 para SSD rápido de desarrollo | G32: Crítico
A33: 3 | B33: Memoria RAM | C33: 16 GB DDR4 3200 MHz · Kingston Fury Beast · 2×8 GB | D33: RAM | E33: 360000 | F33: VS Code + Chrome + Postman + Laravel local corriendo a la vez sin swap | G33: Crítico
A34: 4 | B34: SSD NVMe 1 TB | C34: Kingston NV2 M.2 · Lectura 3.500 MB/s | D34: Almacenamiento | E34: 320000 | F34: OS + proyectos + entornos node_modules + BD local de pruebas | G34: Crítico
A35: 5 | B35: Fuente de poder | C35: Thermaltake Smart 600W · 80+ Bronze · ATX | D35: Alimentación | E35: 240000 | F35: 600W eficiente para Ryzen 5 sin GPU dedicada. Protecciones eléctricas | G35: Crítico
A36: 6 | B36: Gabinete | C36: Thermaltake Versa H17 · Micro-ATX · Panel lateral | D36: Carcasa | E36: 160000 | F36: Compacto para escritorio de trabajo. Buen flujo de aire | G36: Medio
A37: 7 | B37: Monitor 24" FHD | C37: LG 24MK430H · FHD 1080p IPS · 75Hz · HDMI | D37: Display | E37: 660000 | F37: 24" IPS para sesiones largas de programación. Colores precisos para UI/UX | G37: Crítico
A38: 8 | B38: Teclado | C38: Logitech K280e Pro USB · Silencioso · Ergonómico | D38: Periférico | E38: 100000 | F38: Cómodo para largas sesiones de código. Silencioso en trabajo compartido | G38: Alto
A39: 9 | B39: Mouse | C39: Logitech M100 USB · 1000 DPI · Plug & Play | D39: Periférico | E39: 50000 | F39: Confiable y preciso. Sin drivers. Compatible Ubuntu y Windows | G39: Alto
A40: 10 | B40: UPS 750VA | C40: Forza NT-751 · 750VA/375W · 6 tomas · Protección picos | D40: Energía | E40: 380000 | F40: Protege de picos eléctricos frecuentes en Colombia. Esencial para no perder trabajo | G40: Alto
A41: 11 | B41: Audífonos + Mic | C41: HyperX Cloud Stinger · USB · Micrófono integrado | D41: Audio | E41: 230000 | F41: Reuniones Daily Scrum, Sprint Review y comunicación remota con el equipo | G41: Medio
A42: 12 | B42: Webcam HD | C42: Logitech C270 · 720p · USB · Clip monitor | D42: Video | E42: 180000 | F42: Demos Sprint Review, videoconferencias con instructor SENA | G42: Medio
A43: TOTAL PC 4 / PC 5 (cada estación) — valor de referencia, SOLO se presupuesta depreciación | E43: =SUM(E31:E42) -> 3840000
...

Sheet INFRAESTRUCTURA TÉCNICA
A1: Control Store — Aleyual | Infraestructura Técnica | Qué se necesita para que el sistema funcione
A2: Servidor LOCAL físico (PC3) en la tienda — explicación completa: dispositivo, servidor, base de datos, red e IP
A4: A. DISPOSITIVO INICIAL — Lo que necesita el Autoservicio Aleyual para usar el sistema
A5: # | B5: REQUISITO | C5: MÍNIMO NECESARIO | D5: ¿QUÉ SIGNIFICA ESTO? | E5: IMPACTO PARA ALEYUAL
A6: 1 | B6: Dispositivo en caja | C6: PC, laptop o tablet | D6: El sistema es una aplicación WEB — funciona en cualquier dispositivo con navegador, sin instalar nada. | E6: No requiere comprar hardware especializado de punto de venta.
A7: 2 | B7: Navegador web | C7: Chrome, Edge o Firefox actualizado | D7: Probado en navegadores modernos. Versiones muy antiguas pueden no renderizar bien el CSS. | E7: Google Chrome es el más probado y recomendado.
A8: 3 | B8: Conexión a la red local | C8: Cable Ethernet o WiFi | D8: El dispositivo de caja se conecta al servidor PC3 dentro de la misma red local de la tienda (192.168.1.x). | E8: No depende de internet externo para operar — solo de la red interna.
A9: 4 | B9: Impresora de recibos (opcional) | C9: Impresora térmica 58/80mm | D9: No es obligatoria para el MVP, pero mejora la experiencia de venta física en caja. | E9: Impresora térmica USB ~$180.000 COP.
A10: 5 | B10: Lector de código de barras (opcional) | C10: Lector USB tipo pistola | D10: Agiliza la búsqueda de productos en inventario y ventas. | E10: Lector USB básico ~$90.000 COP.
A12: B. SERVIDOR LOCAL (PC3) — Dónde vive el sistema en la tienda
A13: # | B13: COMPONENTE | C13: VALOR | D13: ¿QUÉ SIGNIFICA ESTO? | E13: IMPACTO PARA ALEYUAL
A14: 1 | B14: Tipo de servidor | C14: Físico, local, en la tienda | D14: A diferencia de servicios en la nube, este servidor es un computador real dentro del Autoservicio Aleyual. | E14: El negocio depende de electricidad estable — por eso el UPS es crítico.
A15: 2 | B15: Procesador (CPU) | C15: Intel Core i5-12400 · 6 núcleos | D15: Sin GPU dedicada. 6 núcleos manejan MySQL + PHP-FPM + Nginx simultáneamente sin cuellos de botella. | E15: Suficiente para todo el tráfico diario de una tienda de barrio/autoservicio.
A16: 3 | B16: RAM del servidor | C16: 32 GB DDR4 | D16: Memoria de trabajo. Permite correr base de datos + backend + cache sin quedarse sin memoria (swap). | E16: Sin lentitud en horas pico (mediodía, fin de mes).
A17: 4 | B17: Almacenamiento | C17: SSD 500GB (sistema) + HDD 2TB (datos) | D17: SSD para el sistema operativo (arranque rápido). HDD grande para base de datos y backups históricos. | E17: 2TB equivale a varios años de historial de ventas e imágenes de productos.
A18: 5 | B18: Disponibilidad (uptime) | C18: 24/7 mientras haya electricidad | D18: El servidor está siempre encendido en la tienda — no se 'duerme' como un plan cloud gratuito. | E18: Respuesta inmediata en cada venta, sin esperas de reactivación.
A19: 6 | B19: Protección eléctrica | C19: UPS 850VA — 8 min de autonomía | D19: Si se va la luz, el UPS da tiempo para apagar el servidor de forma segura, evitando corrupción de la base de datos. | E19: CRÍTICO en Colombia por la frecuencia de cortes eléctricos.
A21: C. BASE DE DATOS — Dónde se guarda la información del negocio
A22: # | B22: COMPONENTE | C22: VALOR | D22: ¿QUÉ SIGNIFICA ESTO? | E22: IMPACTO PARA ALEYUAL
A23: 1 | B23: Motor de base de datos | C23: MySQL 8.0 (local, en PC3) | D23: Sistema de gestión de base de datos relacional, instalado directamente en el servidor de la tienda. | E23: Los datos NUNCA salen de la tienda — control total y privacidad.
A24: 2 | B24: Ubicación de los datos | C24: 100% local, en el HDD de 2TB | D24: A diferencia de servicios cloud, toda la información vive físicamente en el Autoservicio Aleyual. | E24: No depende de un proveedor externo para acceder a los datos.
A25: 3 | B25: Capacidad estimada | C25: Varios años de operación | D25: Con 2TB de almacenamiento, la BD puede crecer sin límites prácticos durante toda la vida del negocio. | E25: No hay que migrar ni pagar por más espacio como en planes cloud.
A26: 4 | B26: Backup | C26: Diario, automático (cron 2:00 AM) | D26: Copia de seguridad programada cada noche, guardada en el mismo HDD y replicada en backup externo. | E26: Si algo falla, se puede restaurar la información del día anterior.
A27: 5 | B27: Seguridad de acceso | C27: Solo accesible desde localhost | D27: La base de datos NUNCA se expone directamente a internet — solo el backend en el mismo servidor puede consultarla. | E27: Protección máxima contra accesos externos no autorizados.
A29: D. RED E IP — Cómo se conecta todo dentro de la tienda
A30: # | B30: CONCEPTO | C30: VALOR | D30: ¿QUÉ SIGNIFICA ESTO? | E30: IMPACTO PARA ALEYUAL
A31: 1 | B31: IP del servidor | C31: 192.168.1.100 (fija/estática) | D31: Dirección fija dentro de la red local de la tienda — nunca cambia, así el router se reinicie. | E31: El equipo siempre sabe dónde encontrar el servidor en la red.
A32: 2 | B32: IP del router/gateway | C32: 192.168.1.1 | D32: Puerta de enlace de la red local — conecta la red interna de la tienda con internet. | E32: Configuración estándar de cualquier router doméstico/comercial.
A33: 3 | B33: Puerto HTTP/HTTPS | C33: 80 / 443 | D33: Puertos por donde el navegador de caja se comunica con el servidor (Nginx). | E33: Acceso simple desde cualquier dispositivo en la red local.
A34: 4 | B34: Puerto API / Base de datos | C34: 80/443 (Nginx + PHP) / 3306 (MySQL) | D34: Puertos internos, NUNCA expuestos fuera del servidor — solo accesibles desde localhost. | E34: Máxima seguridad: nadie externo puede tocar la API o la BD directamente.
A35: 5 | B35: WiFi del servidor | C35: Deshabilitado — solo cable Ethernet | D35: El servidor SIEMPRE conectado por cable, nunca WiFi, para máxima estabilidad. | E35: Evita caídas de conexión por interferencia o señal débil.
A36: 6 | B36: Firewall | C36: UFW — solo puertos 22, 80, 443 abiertos | D36: Bloquea automáticamente cualquier intento de conexión a puertos no autorizados. | E36: Protección activa 24/7 sin intervención manual.
A37: 7 | B37: Acceso remoto al sistema | C37: No disponible fuera de la tienda | D37: Al ser un servidor local, NO se puede revisar el sistema desde fuera sin configuración adicional (VPN). | E37: Mayor seguridad, pero el dueño debe estar en la tienda o usar VPN para acceso remoto.
A40: • Este servidor es FÍSICO y LOCAL — vive dentro del Autoservicio Aleyual, a diferencia de soluciones 100% en la nube.
A41: • Ventaja: control total de los datos y sin dependencia de internet para operar internamente.
A42: • Desventaja: requiere mantenimiento físico (UPS, ventilación, backups) y no es accesible remotamente sin VPN.
A43: • Si el negocio crece a múltiples sucursales, se recomienda migrar a una arquitectura híbrida (local + cloud) en una fase futura.

Sheet GASTOS
A1: Aleyual — Control Store | Gastos Administrativos | Arriendo, Servicios y Depreciación
A2: A. ARRIENDO Y SERVICIOS (gastos fijos que cada desarrollador asume trabajando desde casa — 18 meses × 4 desarrolladores)
A3: # | B3: SERVICIO | C3: Costo mensual (COP) c/u | D3: Meses × Desarroll. | E3: COSTO TOTAL
A4: 1 | B4: Luz (energía eléctrica — 30% del recibo) | C4: 150000 | D4: 18 × 4 | E4: =C4*18*4 -> 10800000
A5: 2 | B5: Agua (10% del consumo mensual) | C5: 15000 | D5: 18 × 4 | E5: =C5*18*4 -> 1080000
A6: 3 | B6: Internet — fibra óptica (100% del plan) | C6: 120000 | D6: 18 × 4 | E6: =C6*18*4 -> 8640000
A7: 4 | B7: Papelería e insumos de oficina | C7: 25000 | D7: 18 × 4 | E7: =C7*18*4 -> 1800000
A8: 5 | B8: Arriendo espacio de trabajo (si aplica — trabajo desde casa = $0) | C8: 0 | D8: 18 × 4 | E8: =C8*18*4 -> 0
A9: Total Arriendo y Servicios | E9: =SUM(E4:E8) -> 22320000
A11: NOTA: cada uno de los 4 desarrolladores (A, B, C, D) trabaja desde su propia casa y asume su propio consumo de luz, agua, internet y papelería. Por eso el costo mensual se multiplica por 18 meses trabajados × 4 desarrolladores.
A13: B. DEPRECIACIÓN — 4 EQUIPOS DE TRABAJADORES (PC3 servidor YA EXISTE, no se deprecia) — 18 meses trabajados, método uniforme
A14: COMP | B14: Detalle | C14: COSTO REF. | D14: VIDA ÚTIL / MÉTODO | E14: Dep. Total Proyecto
A15: PC 1 | B15: PC 1 — Trabajador / Desarrollador A | C15: ='SERVIDOR Y EQUIPOS'!E27 -> 3840000 | D15: 60 meses (5 años) · 18 meses trabajados | E15: =ROUND(C15/60*18,0) -> 1152000
A16: PC 2 | B16: PC 2 — Trabajador / Desarrollador B | C16: ='SERVIDOR Y EQUIPOS'!E27 -> 3840000 | D16: 60 meses (5 años) · 18 meses trabajados | E16: =ROUND(C16/60*18,0) -> 1152000
A17: PC 4 | B17: PC 4 — Trabajador / Desarrollador C (NUEVO) | C17: ='SERVIDOR Y EQUIPOS'!E43 -> 3840000 | D17: 60 meses (5 años) · 18 meses trabajados | E17: =ROUND(C17/60*18,0) -> 1152000
A18: PC 5 | B18: PC 5 — Trabajador / Desarrollador D (NUEVO) | C18: ='SERVIDOR Y EQUIPOS'!E43 -> 3840000 | D18: 60 meses (5 años) · 18 meses trabajados | E18: =ROUND(C18/60*18,0) -> 1152000
A19: Fórmula (los 4 equipos, método uniforme): Costo de referencia ÷ 60 meses × 18 meses trabajados.
A20: Total Depreciación (4 equipos de trabajadores) | E20: =ROUND(SUM(E15:E18),0) -> 4608000
A22: NOTA: PC 3 (servidor de la tienda) YA ES PROPIEDAD de Autoservicio Aleyual — no se compra ni se deprecia en este proyecto. Solo se deprecian los 4 equipos de los trabajadores.
A24: TOTAL GASTOS ADMINISTRATIVOS (Servicios + Depreciación) | E24: =ROUND(E9+E20,0) -> 26928000
A26: Fuentes de costos de servicios (Colombia, Bogotá/Soacha 2026):
A27: • Luz: promedio factura residencial Bogotá $400K–$600K/mes. Proporción 30% para oficina = $120K–$180K/mes. Ref: codensa.com.co
A28: • Internet fibra óptica: Claro Colombia $99.900–$149.900/mes (plan 100–200 Mbps). Ref: claro.com.co/personas/servicios/internet/
A29: • Dominio .co: nic.co — $89.000/año registro y renovación. Dominio .com: GoDaddy ~$50.000/año
A30: • Depreciación: método de línea recta. Vida útil laptops: 5 años (60 meses). Los 4 equipos se deprecian de forma uniforme por 18 meses trabajados.

Sheet RECURSOS TECNOLÓGICOS
A1: Aleyual — Control Store | Recursos Tecnológicos | Hardware · Software · Cloud
A2: A. HARDWARE — DISPOSITIVOS
A3: # | B3: Ítem | C3: Opción / Especificación | D3: ¿Aplica? | E3: COSTO
A4: 1 | B4: DISPOSITIVO FINAL
A5: 1.1 | B5: Cliente — PC del usuario (2 existentes) | C5: Equipo propio del cliente | D5: ✓ Ya existe | E5: 0
A6: 1.2 | B6: Servidor — PC3 de la tienda | C6: YA EXISTE — propiedad de Autoservicio Aleyual (ver hoja SERVIDOR Y EQUIPOS) | D6: ✓ Ya existe — $0 | E6: 0
A7: 1.3 | B7: Servidor Físico | C7: Reutilizar 1 PC como servidor local | D7: ✓ Ya existe | E7: 0
B8: Procesador del servidor | C8: Intel Core i5/i7 (equipo existente) | D8: Equipo cliente | E8: 0
B9: Memoria RAM | C9: 8–16 GB (equipo existente) | D9: Equipo cliente | E9: 0
B10: Disco Duro / SSD | C10: 500 GB–1 TB (equipo existente) | D10: Equipo cliente | E10: 0
A11: Total Hardware | E11: 0
A13: B. SOFTWARE — LICENCIAS Y HERRAMIENTAS
A14: # | B14: Software | C14: Versión / Proveedor | D14: Costo / mes | E14: COSTO TOTAL
A15: 1 | B15: Software de Sistema | C15: Ubuntu Server 24.04 LTS | D15: Gratuito — Open Source | E15: 0
A16: 1.1 | B16: Software de Protección | C16: ClamAV + UFW Firewall | D16: Gratuito — Open Source | E16: 0
A17: 2 | B17: Software de Aplicación | C17: Sistema Aleyual (desarrollo propio) | D17: Producto del proyecto | E17: 0
A18: 3 | B18: Software de Desarrollo | C18: VS Code, Git, Postman, DBeaver | D18: Gratuito — Open Source | E18: 0
A19: 4 | B19: Lenguajes | C19: PHP 8.2, JavaScript (ES6+) | D19: Gratuito — Open Source | E19: 0
A20: 5 | B20: Frameworks | C20: Laravel 11, Bootstrap 5, React Native | D20: Gratuito — Open Source | E20: 0
A21: 6 | B21: Librerías | C21: npm packages, pip packages | D21: Gratuito — Open Source | E21: 0
A22: 7 | B22: Licencias (Soft de Terceros) | C22: No requeridas — stack open source | D22: N/A | E22: 0
A23: 8 | B23: HOSTING (Alojamiento) | C23: AWS — ver sección C | D23: Ver sección C | E23: 0
A24: 9 | B24: Dominio (DNS) | C24: dominio.com.co anual (~$1.000.000/año) | D24: $83.333 × 20 meses | E24: 83333
A25: Total Software | E25: =SUM(E15:E24) -> 83333
A27: C. SERVICIOS CLOUD — AWS (Recomendado) / Azure / Google Cloud
A28: # | B28: Servicio | C28: Plan / Instancia | D28: Costo/mes (COP) | E28: COSTO TOTAL
A29: C.1 | B29: AWS (Amazon Web Services) | C29: Proveedor recomendado — región us-east-1 | D29: Sí
A30: C.1.1 | B30: EC2 t3.small — Servidor Web | C30: 1 vCPU, 2 GB RAM — USD$15/mes × $4.200 COP × 6 meses | D30: 63000 | E30: 378000
A31: C.1.2 | B31: RDS MySQL t3.micro — Base de Datos | C31: 1 vCPU, 1 GB RAM — USD$10/mes × $4.200 COP × 4 meses | D31: 42000 | E31: 168000
A32: C.1.3 | B32: S3 Standard — Almacenamiento | C32: ~5 GB archivos e imágenes — USD$2/mes × $4.200 COP × 6 meses | D32: 8400 | E32: 50400
A33: C.1.4 | B33: Dirección IP pública (Elastic IP) | C33: Incluida sin costo con instancia activa | D33: — | E33: 0
A34: C.2 | B34: Azure (alternativa a AWS) | C34: Azure App Service + Azure SQL | D34: No acumular con AWS
A35: C.3 | B35: Google Cloud (alternativa) | C35: GCP App Engine + Cloud SQL | D35: No acumular con AWS
B36: Dirección IP / Puertos | C36: Configurados en Security Groups de AWS | D36: — | E36: 0
B37: Dominio (DNS) | C37: Ver Software sección B, ítem 9 | D37: — | E37: 0
A38: Total Hosting y Cloud (AWS) | E38: =SUM(E29:E37) -> 596400
A40: TOTAL RECURSOS TECNOLÓGICOS (Software + Hosting) | E40: =E25+E38 -> 679733
A42: Fuentes de precios cloud (jun 2026):
A43: • AWS Precios EC2 bajo demanda: https://aws.amazon.com/es/ec2/pricing/on-demand/ — EC2 t3.small Linux us-east-1: $0.0208 USD/hora ≈ $15 USD/mes
A44: • AWS Calculator: https://calculator.aws/pricing/2/metahtml (calculadora oficial de costos AWS)
...

Sheet CONTRATO RECOMENDADO
A1: Aleyual — Control Store | Contrato Recomendado | Prestación de Servicios
A2: ✅ RECOMENDADO: Prestación de Servicios (Art. 34 C.S.T.)
B3: Base legal | C3: Art. 34 Código Sustantivo del Trabajo. Ley 80/1993 (sector servicios). Estándar del sector TI en Colombia (MinTIC, SENA).
B4: ¿Por qué es el más adecuado? | C4: Proyectos de software con entregables por trimestre no generan subordinación permanente. El sector TI colombiano usa esta modalidad en más del 80% de sus proyectos.
B5: Ahorro prestacional | C5: Sin cesantías, prima, vacaciones pagadas por el contratante, dotación ni EPS/AFP a cargo del empleador. Ahorro real del 42–52% frente a un contrato laboral.
B6: Pago por días efectivos | C6: Los ~86 días de descanso (Semana Santa, vacaciones, Navidad) NO se facturan. Solo se paga por tiempo efectivamente trabajado.
B7: Flexibilidad por fase | C7: Vincular/desvincular profesionales por trimestre sin procesos de liquidación. Ideal para Gestor BD (solo T3–T4) y Arquitecto (fases puntuales).
B8: Pago por entregables | C8: El contrato especifica entregables medibles por trimestre: mockups aprobados, scripts DDL/DML, API documentada, pruebas ISO 25010. No por asistencia.
B9: Obligación del contratista | C9: El profesional asume salud (12.5%) y pensión (16%) propias. Negociar honorario 25–30% superior al salario de mercado equivalente para compensar.
B10: Cláusula NDA (confidencialidad) | C10: Incluir Non-Disclosure Agreement sobre código fuente, arquitectura, base de datos y datos del cliente Autoservicio Aleyual.
B11: Duración recomendada | C11: Contratos por trimestre (3–4 meses) renovables. Permite no renovar si el entregable no se cumple en tiempo y forma.
B12: Riesgo contrato realidad | C12: No imponer horario fijo ni supervisión directa constante. Si hay subordinación + horario + herramientas del contratante → puede reclamar relación laboral.
A13: ❌ Otras modalidades — por qué NO aplican
B14: Contrato a término fijo | C14: Incluye TODAS las prestaciones sociales (+52% costo real). Solo para empleados permanentes de la empresa ejecutora. No aplica para equipo TI externo.
B15: Contrato de obra o labor | C15: También exige prestaciones. Aplica cuando el trabajador pertenece a la empresa ejecutora del proyecto.
B16: Contrato indefinido | C16: Máximo costo, mínima flexibilidad. Imposible terminar sin indemnización. Totalmente inadecuado para proyecto con fecha de entrega definida.
A18: Fuentes legales y de referencia:
A19: • Código Sustantivo del Trabajo (C.S.T.) — Art. 34: trabajadores independientes: https://leyes.co/codigo_sustantivo_del_trabajo/34.htm
A20: • DIAN — Contratos de prestación de servicios y retención en la fuente: https://www.dian.gov.co/
A21: • MinTIC — Contratación TI en Colombia: https://www.mintic.gov.co/portal/inicio/
A22: • SENA Oferta Educativa y Contratos: https://www.sena.edu.co/

Sheet FUENTES
A1: Control Store — Aleyual | Fuentes Verificadas | Salarios, Cloud, Legal y Hardware
A2: Toda la información fue verificada directamente en las páginas oficiales de cada fuente — junio 2026
A4: A. SALARIOS — Mercado de desarrolladores en Colombia
A5: # | B5: FUENTE | C5: RANGO REPORTADO | D5: LINK OFICIAL | E5: NOTA
A6: 1 | B6: Glassdoor Colombia | C6: $3.0M–$6.8M/mes | D6: https://www.glassdoor.com.mx/Sueldos/colombia-desarrollador-de-software-sueldo-SRCH_IL.0,8_IN47_KO9,34.htm | E6: Dev Software según experiencia (2025-2026)
A7: 2 | B7: Indeed Colombia | C7: ~$3.1M/mes promedio | D7: https://co.indeed.com/career/desarrollador-de-software/salaries | E7: Actualizado mayo 2026
A8: 3 | B8: tusalario.org | C8: $3.2M–$17.4M/mes | D8: https://tusalario.org/colombia/carrera/funcion-y-salario/desarrolladores-de-software | E8: Rango amplio según nivel
A9: 4 | B9: Coderhouse Colombia | C9: $5M–$9M+/mes | D9: https://www.coderhouse.com/us/sueldos/sueldo-desarrollador-full-stack-colombia-2025 | E9: Full Stack Mid/Senior
A10: 5 | B10: Talently | C10: $4.8M–$25M/mes | D10: https://talently.tech/herramientas/colombia/salario | E10: Junior a Senior, datos 2024-2026
A12: B. SERVICIOS CLOUD — AWS y alternativas (despliegue T7)
A13: # | B13: PROVEEDOR / SERVICIO | C13: USO | D13: LINK OFICIAL | E13: NOTA
A14: 1 | B14: AWS EC2 — Pricing on-demand | C14: Servidor virtual T7 | D14: https://aws.amazon.com/es/ec2/pricing/on-demand/ | E14: EC2 t3.small: $0.0208 USD/hora
A15: 2 | B15: AWS Calculator | C15: Estimación de costos | D15: https://calculator.aws/pricing/2/metahtml | E15: Calculadora oficial AWS
A16: 3 | B16: AWS RDS MySQL | C16: Base de datos en la nube | D16: https://aws.amazon.com/es/rds/mysql/pricing/ | E16: Free Tier 750h/mes primeros 12 meses
A17: 4 | B17: AWS S3 | C17: Almacenamiento de imágenes | D17: https://aws.amazon.com/es/s3/pricing/ | E17: $0.023 USD/GB/mes
A18: 5 | B18: Azure Calculator (alternativa) | C18: Comparación de costos | D18: https://azure.microsoft.com/es-es/pricing/calculator/ | E18: Alternativa a AWS
A19: 6 | B19: Google Cloud Calculator (alternativa) | C19: Comparación de costos | D19: https://cloud.google.com/products/calculator | E19: Alternativa a AWS
A20: 7 | B20: nic.co — Dominio .com.co | C20: Dominio del sistema | D20: https://nic.co/ | E20: $89.000 COP/año
A21: 8 | B21: Banco de la República — TRM | C21: Tasa de cambio USD/COP | D21: https://www.banrep.gov.co/es/estadisticas/trm | E21: Referencia jun 2026: ~$4.200 COP/USD
A23: C. SERVICIOS Y COSTOS — Referencias Colombia
A24: # | B24: SERVICIO | C24: VALOR REF. | D24: LINK OFICIAL | E24: NOTA
A25: 1 | B25: Codensa — Energía eléctrica | C25: $400K–$600K/mes | D25: https://www.codensa.com.co | E25: Factura residencial Bogotá promedio
A26: 2 | B26: Claro — Internet fibra óptica | C26: $99.900–$149.900/mes | D26: https://www.claro.com.co/personas/servicios/internet/ | E26: Plan 100-200 Mbps
A27: 3 | B27: Alkosto — Laptops y equipos | C27: Variable | D27: https://www.alkosto.com/computadores-y-tablets/computadores-portatiles | E27: Referencia componentes PC1/PC2/PC3
A28: 4 | B28: Éxito — Tecnología | C28: Variable | D28: https://www.exito.com/tecnologia/computadores/portatiles | E28: Referencia componentes
A30: D. MARCO LEGAL Y NORMATIVO
A31: # | B31: CONCEPTO | C31: VALOR/FUENTE | D31: LINK OFICIAL | E31: NOTA
A32: 1 | B32: Contrato — Prestación de Servicios | C32: Art. 34 C.S.T. | D32: https://leyes.co/codigo_sustantivo_del_trabajo/34.htm | E32: Base legal del contrato del equipo
A33: 2 | B33: DIAN — Retención en la fuente | C33: Contratos de servicios | D33: https://www.dian.gov.co/ | E33: Régimen tributario aplicable
A34: 3 | B34: MinTIC — Contratación TI | C34: Normativa sector TI | D34: https://www.mintic.gov.co/portal/inicio/ | E34: Contratación TI en Colombia
A35: 4 | B35: SENA — Oferta educativa | C35: Programa ADSO | D35: https://www.sena.edu.co/ | E35: Marco del proyecto formativo
A36: 5 | B36: ISO/IEC 25010 | C36: Modelo de calidad de software | D36: https://www.iso.org/standard/35733.html | E36: Estándar usado en pruebas T7
A39: • Todos los enlaces son clicables directamente desde Excel (Ctrl+clic si no responde al primer clic).
A40: • Información verificada en junio de 2026. Los proveedores cloud y precios de mercado cambian con frecuencia.
A41: • Precios de hardware y servicios son de referencia; confirmar vigencia antes de la compra real.
